Workbook

Sheet Baukostenberechnung
A1: ZEV Baukostenberechnung für Mehrfamilienhäuser | D1: Status | E1: Entwurf V2
D2: Datum | E2: 2026-02-22
A4: Legende
A5: Eingabefeld (editierbar)
A6: Berechnetes Feld (Formel)
A7: Verknüpfung aus anderem Blatt
A9: BASISANGABEN
A10: Objektadresse | B10: Zelgstrasse 25, Bern
A11: Anzahl Wohnungen | B11: 9 | C11: Zahl eingeben
A12: Wärmepumpe vorhanden | B12: nein
A13: eMobilitätszähler vorhanden | B13: nein
A14: PV Anlage vorhanden | B14: ja
A15: Boiler | B15: nein
A17: STROMLIEFERANT & TARIF
A18: Stromlieferant | B18: EWB
A19: Strompreis (Rp./kWh) | B19: =IF(B18="EWB",Hilfstabelle!B39,Hilfstabelle!C39) -> 33.48 | C19: aus Tariftabelle
A20: Einspeisevergütung 2026 inkl. HKN (Rp./kWh) | B20: =IF(B18="EWB",Hilfstabelle!B40,Hilfstabelle!C40) -> 10.96
A21: ZEV Tarif 80% des Strompreises (Rp./kWh) | B21: =ROUND(B19*0.8,2) -> 26.78
A22: Herstellkosten PV Strom (Rp./kWh) | B22: ='Kalk PV Strom HK'!C23*100 -> 5.6054763 | C22: aus PV HK-Berechnung
A23: Stromzählerkosten (CHF/Monat) | B23: =IF(B18="EWB",Hilfstabelle!B43,Hilfstabelle!C43) -> 8.43
A25: DIENSTLEISTUNGSMODULE
A26: Abrechnungsmodul | B26: L | C26: L=Voll / M=Standard / S=Basis
A27: Machbarkeitsabklärung | B27: ja
A28: ZEV Vertragserstellung | B28: ja
A29: PV & EMS Nutzerportal | B29: ja
A30: Internetzugang (für Server) | B30: ja
A31: Begehung | B31: ja
A33: ZEV KOSTEN (ZUSAMMENFASSUNG)
A34: Beschreibung | B34: Betrag (CHF) | C34: Details
A35: Einmalige Kosten | B35: =Hilfstabelle!B23+Hilfstabelle!B26 -> 8500
A36: davon Grundkosten (fix) | B36: =Hilfstabelle!B23 -> 4500
A37: davon variable Kosten (pro Zähler) | B37: =Hilfstabelle!B26 -> 4000 | C37: =Hilfstabelle!B12&" Zähler × CHF "&TEXT(Hilfstabelle!B13,"#,##0")&"/Stk" -> 10 Zähler × CHF 400/Stk
A38: Wiederkehrende Kosten (pro Jahr) | B38: =Hilfstabelle!B32+Hilfstabelle!B35 -> 1053
A39: davon Grundkosten (fix) | B39: =Hilfstabelle!B32 -> 213
A40: davon variable Kosten (pro NE) | B40: =Hilfstabelle!B35 -> 840 | C40: ="("&TEXT(B11+1,"0")&" NE × CHF "&TEXT(Hilfstabelle!B14,"#,##0")&"/NE/Jahr)" -> (10 NE × CHF 84/NE/Jahr)
A42: PV ANLAGE
A43: Kosten PV Anlage (CHF exkl. MWST) | B43: 31300
A44: Förderung pronovo.ch (CHF) | B44: -11099
A45: Peakleistung PVA (kWp) | B45: 31.02
A46: Stromproduktion pro Jahr (kWh) | B46: =B45*1000 -> 31020 | C46: Richtwert: 1000 kWh/kWp
...

Sheet Kalk PV Strom HK
A1: Berechnung der Herstellungskosten kWh PV-Anlage
B3: Objekt | C3: =Baukostenberechnung!B10 -> Zelgstrasse 25, Bern
B5: Anlage (kWp) | C5: =Baukostenberechnung!B45 -> 31.02 | D5: kWp
B6: Stromjahresertrag erwartet | C6: =Baukostenberechnung!B46 -> 31020 | D6: kWh
B8: INVESTITIONSKOSTEN | C8: Betrag
B9: Offerte PV Anlage exkl. MWST | C9: =Baukostenberechnung!B43 -> 31300 | D9: CHF
B10: Rückvergütung pronovo.ch | C10: =Baukostenberechnung!B44 -> -11099 | D10: CHF
B11: Investitionsbetrag netto | C11: =C9+C10 -> 20201 | D11: CHF
B13: BETRIEBSKOSTEN ÜBER 25 JAHRE
B14: Unterhaltskosten (1.5% p.a. auf Invest × 25 J.) | C14: =C11*0.015*25 -> 7575.375 | D14: CHF
B15: Austausch Wechselrichter | C15: 4000 | D15: CHF
B16: Lastgangmessung (CHF 10/Mt × 25 J.) | C16: =10*12*25 -> 3000 | D16: CHF
B17: PV Gesamtkosten über 25 Jahre | C17: =SUM(C11:C16) -> 34776.375 | D17: CHF
B19: STROMPRODUKTION ÜBER 25 JAHRE
B20: Produktionsertrag (25 Jahre) | C20: =C6*25 -> 775500 | D20: kWh
B21: mit Degradation 80% | C21: =C20*0.8 -> 620400 | D21: kWh
B23: PV Herstellungskosten pro kWh | C23: =C17/C21 -> 0.056054763

Sheet Preismodulkatalog
B1: Produktpreiskatalog: Optimierung PVA Rentabilität
B2: nach Modulkastenprinzip, alle Kosten in CHF inkl. MWST
B4: Dienstleistungsmodule | C4: Einmalig | D4: Jährlich | E4: Hardware | F4: Bemerkungen
B5: Abrechnungsmodul LEG | F5: Tarif des lokalen Energieversorgers
B6: Abrechnungsmodul L: ZEV/vZEV pro NE | C6: 50 | D6: 84 | F6: Datenaufbereitung, Rechnungsversand PDF halbjährlich mit 2 Mahnläufe
B7: Abrechnungsmodul M: ZEV/vZEV pro NE | C7: 50 | D7: 36 | F7: Datenaufbereitung und Rechnungsversand per PDF
B8: Abrechnungsmodul S: ZEV/vZEV pro NE | C8: 25 | D8: 24 | F8: Datenaufbereitung für Verarbeitung Liegenschaftsverwaltung
B9: Server M: autom. Zählerauslesung (>15 NE) | C9: 2950 | D9: 120 | F9: Invisia Server > 15 NE
B10: Server S: autom. Zählerauslesung (≤15 NE) | C10: 1950 | D10: 48 | F10: Solarmanager bis 15 NE
B11: PV & EMS Nutzerportal | C11: 600 | D11: 121 | F11: Stromverlauf & Rechnungen pro NE
B12: Internetzugang | C12: 400 | D12: 44
B13: Einbau Server | C13: 500
B14: Stromzähler: Integration & Lieferung pro NE | C14: 350
B15: ZEV/vZEV Vertrag | C15: 500 | F15: Vertrag bis 10 TL, danach +50 CHF/TL
B16: Begehung | C16: 300
B17: Machbarkeitsabklärung | C17: 250 | F17: Wird bei PVA Bestellung gutgeschrieben

Sheet Hilfstabelle
A1: Hilfstabelle für Baukostenberechnung
A2: Alle Berechnungen referenzieren dynamisch die Modulauswahl im Hauptblatt
A4: ZWISCHENBERECHNUNGEN | B4: Wert | C4: Formel / Logik
A5: Servertyp (automatisch) | B5: =IF(Baukostenberechnung!B11<=15,"S","M") -> S | C5: S wenn ≤15 NE, M wenn >15 NE
A6: Server Kosten einmalig | B6: =IF(B5="S",Preismodulkatalog!C10,Preismodulkatalog!C9) -> 1950 | C6: Server S=1950, Server M=2950
A7: Server Kosten jährlich | B7: =IF(B5="S",Preismodulkatalog!D10,Preismodulkatalog!D9) -> 48
A8: Einbau Server | B8: =Preismodulkatalog!C13 -> 500
A9: Abrechnungsmodul einmalig/NE | B9: =IF(Baukostenberechnung!B26="L",Preismodulkatalog!C6,IF(Baukostenberechnung!B26="M",Preismodulkatalog!C7,Preismodulkatalog!C8)) -> 50 | C9: L=50, M=50, S=25
A10: Abrechnungsmodul jährlich/NE | B10: =IF(Baukostenberechnung!B26="L",Preismodulkatalog!D6,IF(Baukostenberechnung!B26="M",Preismodulkatalog!D7,Preismodulkatalog!D8)) -> 84 | C10: L=84, M=36, S=24
A12: Anzahl Zähler total | B12: =Baukostenberechnung!B11+1+IF(Baukostenberechnung!B12="ja",1,0)+IF(Baukostenberechnung!B13="ja",1,0) -> 10 | C12: Wohnungen + 1 Allgemein + WP + eMobil
A13: Kosten pro Zähler (Hardware + Einrichtung) | B13: =Preismodulkatalog!C14+B9 -> 400 | C13: Zähler 350 + Abrechnungsmodul einmalig
A14: Kosten Abrechnungsmodul jährlich pro NE | B14: =B10 -> 84
A16: EINMALIGE KOSTEN (GRUNDKOSTEN) | B16: CHF | C16: Bedingung
A17: Server (inkl. Einbau) | B17: =B6+B8 -> 2450 | C17: immer inkludiert (Typ abhängig von Anz. NE)
A18: PV & EMS Nutzerportal | B18: =IF(Baukostenberechnung!B29="ja",Preismodulkatalog!C11,0) -> 600 | C18: =IF(Baukostenberechnung!B29="ja","✓ aktiviert","✗ deaktiviert") -> ✓ aktiviert
A19: Internetzugang | B19: =IF(Baukostenberechnung!B30="ja",Preismodulkatalog!C12,0) -> 400 | C19: =IF(Baukostenberechnung!B30="ja","✓ aktiviert","✗ deaktiviert") -> ✓ aktiviert
A20: Machbarkeitsabklärung | B20: =IF(Baukostenberechnung!B27="ja",Preismodulkatalog!C17,0) -> 250 | C20: =IF(Baukostenberechnung!B27="ja","✓ aktiviert","✗ deaktiviert") -> ✓ aktiviert
A21: Begehung | B21: =IF(Baukostenberechnung!B31="ja",Preismodulkatalog!C16,0) -> 300 | C21: =IF(Baukostenberechnung!B31="ja","✓ aktiviert","✗ deaktiviert") -> ✓ aktiviert
A22: ZEV Vertragserstellung | B22: =IF(Baukostenberechnung!B28="ja",Preismodulkatalog!C15+IF(Baukostenberechnung!B11>10,(Baukostenberechnung!B11-10)*50,0),0) -> 500 | C22: =IF(Baukostenberechnung!B28="ja","✓ 500 + "&IF(Baukostenberechnung!B11>10,(Baukostenberechnung!B11-10)&" × 50 Zusatz-TL","bis 10 TL inkl."),"✗ deaktiviert") -> ✓ 500 + bis 10 TL inkl.
A23: Grundkosten einmalig TOTAL | B23: =SUM(B17:B22) -> 4500
A25: EINMALIGE KOSTEN (VARIABEL) | B25: CHF
A26: Zähler × Kosten pro Stück | B26: =B12*B13 -> 4000 | C26: =TEXT(B12,"0")&" Zähler × CHF "&TEXT(B13,"#,##0") -> 10 Zähler × CHF 400
A28: WIEDERKEHRENDE KOSTEN (pro Jahr) | B28: CHF/Jahr
A29: PV & EMS Nutzerportal | B29: =IF(Baukostenberechnung!B29="ja",Preismodulkatalog!D11,0) -> 121
A30: Server jährlich | B30: =B7 -> 48
A31: Internetzugang jährlich | B31: =IF(Baukostenberechnung!B30="ja",Preismodulkatalog!D12,0) -> 44
A32: Grundkosten wiederkehrend TOTAL | B32: =SUM(B29:B31) -> 213
A34: Abrechnung pro NE × Anzahl NE | B34: =(Baukostenberechnung!B11+1)*B14 -> 840 | C34: =TEXT(Baukostenberechnung!B11+1,"0")&" NE × CHF "&TEXT(B14,"#,##0")&"/NE" -> 10 NE × CHF 84/NE
A35: Variable Kosten wiederkehrend TOTAL | B35: =B34 -> 840
A38: TARIFE FÜR KENNZAHLENBERECHNUNG | B38: EWB (Rp./kWh) | C38: BKW (Rp./kWh)
A39: Strompreis | B39: =14.05+13.3+0.29+0.05+0.44+2.86+2.49 -> 33.48 | C39: 22.1
A40: Einspeisevergütung 2026 inkl. HKN | B40: 10.96 | C40: 9
A41: ZEV Tarif 80% des Strompreises | B41: =ROUND(B39*0.8,2) -> 26.78 | C41: =ROUND(C39*0.8,2) -> 17.68
A42: Herstellkosten PV Strom | B42: =ROUND('Kalk PV Strom HK'!C23*100,2) -> 5.61 | C42: 8
A43: Stromzählerkosten pro Monat | B43: 8.43 | C43: =214/12+1.081 -> 18.914333
A46: ZUSAMMENFASSUNG (Referenz für Hauptblatt)
